<?xml version="1.0"?>

<robot name="armA" xmlns:xacro="http://www.ros.org/wiki/xacro">

    <xacro:include filename="$(find arm_01)/description/xacro/armA.gazebo_config_control.xacro" />
    <xacro:include filename="$(find arm_01)/description/xacro/armA.transmission.xacro" />
    <xacro:include filename="$(find arm_01)/description/xacro/armA.internal_config.xacro" />
    <xacro:include filename="$(find arm_01)/description/xacro/armA.bumper_config.xacro" />


    <xacro:macro name="armA" params="namespace">
        
        <!-- Base -->
        <link name="base_0">
            <inertial>
                <mass value="3.635"/>
                <origin xyz="4e-06   -0.001     0.082"/>
                <inertia ixx="0.02216" ixy="5.8e-06" ixz="6.2e-06" iyy="0.02"
                    iyz="-5.3e-05"
                    izz="0.02"/>
            </inertial>
            <visual>
                <origin rpy="0 0 0" xyz="0 0 0" />
                <geometry>
                    <mesh filename="file:///$(find arm_01)/description/meshes/armA/armA_0.stl" 
                        scale="0.004 0.004 0.004" />
                </geometry>
                <material name="gray">
                    <color rgba="0.5 0.5 0.5 1"/>
                </material>                  
            </visual>
            <collision>
                <geometry>
                    <mesh filename="file:///$(find arm_01)/description/meshes/armA/armA_0.stl" 
                        scale="0.004 0.004 0.004" />
                </geometry>
              </collision>
        </link>


        <!-- joint 1 -->
        <joint name="joint1" type="revolute">
            <parent link="base_0" />
            <child link="link1" />
            <origin rpy="0 0 0" xyz="0 0 0.114" />
            <axis xyz="0 0 1" />
            <limit effort="411" lower="-6.2832" upper="6.2832" velocity="3.1416"/>
            <dynamics damping="60.0" friction="4.0" />
        </joint>

        <!-- Link 1 -->
        <link name="link1">
            <inertial>
                <mass value="7.9"/>
                <origin xyz="4.4e-05    0.029982    -0.01112"/>
                <inertia ixx="0.046" ixy="1.28e-05" ixz="-3.6e-05" iyy="0.03"
                    iyz="-0.003"
                    izz="0.04"/>
            </inertial>
            <collision>
                <geometry>
                    <cylinder radius="0.08" length="0.2"/>
                </geometry>
            </collision>
            <visual>
                <origin rpy="0 0 0" xyz="0 0 0" />
                <geometry>
                    <mesh filename="file:///$(find arm_01)/description/meshes/armA/armA_1.stl" 
                        scale="0.004 0.004 0.004" />
                </geometry>
                <material name="white">
                    <color rgba="1 1 1 1"/>
                </material>                  
            </visual>
        </link>


        <!-- joint2 -->
        <!-- origin rpy="0 -1.571 -1.571" xyz="0 0.040 0" / -->
        <joint name="joint2" type="revolute">
            <parent link="link1" />
            <child link="link2" />
            <origin rpy="0 0 0" xyz="0 0.082 0.080" />
            <axis xyz="0 1 0" />
            <limit effort="411" lower="-6.2832" upper="6.2832" velocity="3.1416"/>
            <dynamics damping="50.0" friction="3.0" />        
        </joint>
        
        <!-- Link 2 -->
        <link name="link2">
            <inertial>
                <mass value="10.985"/>
                <origin xyz="0.2    0.0014     0.13"/>
                <inertia ixx="0.04" ixy="-0.005" ixz="-0.01" iyy="0.7" iyz="-2.8e-05"
                    izz="0.67"/>
            </inertial>
            <collision>
                <origin rpy="0 -1.571 0" xyz="0.3 0 0.1525" />
                <geometry>
                    <cylinder radius="0.08" length="0.6"/>
                </geometry>
            </collision>
            <visual>
                <origin rpy="0 0 0" xyz="0 0.082 -0.082" />
                <geometry>
                    <mesh filename="file:///$(find arm_01)/description/meshes/armA/armA_2.stl" 
                        scale="0.004 0.004 0.004" />
                </geometry>
                <material name="gray">
                    <color rgba="0.5 0.5 0.5 1"/>
                </material>                 
            </visual>
        </link>

        <joint name="joint3" type="revolute">
            <parent link="link2" />
            <child link="link3" />
            <origin rpy="0 0 0" xyz="0 -0.082 0.500" />
            <axis xyz="0 1 0" />
            <limit effort="194" lower="-2.7925" upper="2.7925" velocity="3.1416"/>
            <dynamics damping="40.0" friction="2.0"/>
        </joint>
        
        <!-- cylinder radius="0.08" length="0.2"/ -->

        <link name="link3">
            <inertial>
                <mass value="2.881"/>
                <origin xyz="8.5e-05   -0.0025    0.03"/>
                <inertia ixx="0.013" ixy="-5.4e-06" ixz="1.64e-05" iyy="0.01"
                    iyz="-0.0002"
                    izz="0.008"/>
            </inertial>
            <collision>
                <geometry>
                    <mesh filename="file:///$(find arm_01)/description/meshes/armA/armA_3.stl" 
                        scale="0.004 0.004 0.004" />
                </geometry>
            </collision>            
            <visual>
                <origin rpy="0 0 0" xyz="0 0 -0.080" />
                <geometry>
                    <mesh filename="file:///$(find arm_01)/description/meshes/armA/armA_3.stl" 
                        scale="0.004 0.004 0.004" />
                </geometry>
                <material name="white">
                    <color rgba="1 1 1 1"/>
                </material>                  
            </visual>
        </link>


        <!-- joint4 -->
        <joint name="joint4" type="revolute">
            <parent link="link3" />
            <child link="link4" />
            <origin rpy="0 0 0" xyz="0 0 0.262" />
            <axis xyz="0 0 1" />
            <limit effort="50" lower="-6.2832" upper="6.2832" velocity="6.2832"/>
            <dynamics damping="20.0" friction="1.0" />
        </joint>

        <link name="link4">
            <inertial>
                <mass value="3.273"/>
                <origin xyz="-9.6e-05    0.085    -0.14"/>
                <inertia ixx="0.12" ixy="2.4e-05" ixz="2.5e-05" iyy="0.11" iyz="-0.028"
                    izz="0.017"/>
            </inertial>
            <collision>
                <origin rpy="-0.46 0 0" xyz="0 0.075 -0.2" />
                <geometry>
                    <cylinder radius="0.05" length="0.4"/>
                </geometry>
            </collision>
            <visual>
                <origin rpy="0 0 0" xyz="0 0 0" />
                <geometry>
                    <mesh filename="file:///$(find arm_01)/description/meshes/armA/armA_4.stl" 
                        scale="0.004 0.004 0.004" />
                </geometry>
                <material name="gray">
                    <color rgba="0.5 0.5 0.5 1"/>
                </material>                 
            </visual>
        </link>

        <!-- origin rpy="-1.571 0 0" xyz="0 0 0" / -->

        <joint name="joint5" type="revolute">
            <parent link="link4" />
            <child link="link5" />
            <origin rpy="0 0 0" xyz="0 0.082 0.24" />
            <axis xyz="0 1 0" />
            <limit effort="50" lower="-6.2832" upper="6.2832" velocity="6.2832"/>
            <dynamics damping="10.0" friction="1.0" />
        </joint>

        <link name="link5">
            <inertial>
                <mass value="2.141"/>
                <origin xyz="0.0001   -0.003     0.015"/>
                <inertia ixx="0.013" ixy="-4.7e-06" ixz="8.6e-06" iyy="0.007"
                    iyz="-6.0e-05"
                    izz="0.009"/>
            </inertial>
            <collision>
                <origin rpy="1.571 0 0" xyz="0 0 0" />
                <geometry>
                    <cylinder radius="0.06" length="0.15"/>
                </geometry>
            </collision>
            <visual>
                <origin rpy="0 0 0" xyz="0 0.082 -0.08" />
                <geometry>
                    <mesh filename="file:///$(find arm_01)/description/meshes/armA/armA_5.stl" 
                        scale="0.004 0.004 0.004" />
                </geometry>
                <material name="white">
                    <color rgba="1 1 1 1"/>
                </material>                  
            </visual>
        </link>

        <joint name="joint6" type="revolute">
            <parent link="link5" />
            <child link="link6" />
            <origin rpy="0 0 0" xyz="0 0.082 0.08" />
            <axis xyz="0 0 1" />
            <limit effort="50" lower="-6.2832" upper="6.2832" velocity="6.2832"/>
            <dynamics damping="10.0" friction="1.0" />
        </joint>

        <link name="link6">
            <inertial>
                <mass value="0.784"/>
                <origin xyz="-1.9e-05      -6e-06    -0.05"/>
                <inertia ixx="0.0067" ixy="5.24e-06" ixz="2.5e-06" iyy="0.0048"
                    iyz="8.37e-06"
                    izz="0.006"/>
            </inertial>
            <visual>
                <origin rpy="0 0 0" xyz="0 0 0" />
                <geometry>
                    <mesh filename="file:///$(find arm_01)/description/meshes/armA/armA_6.stl" 
                        scale="0.004 0.004 0.004" />
                </geometry>
                <material name="gray">
                    <color rgba="0.5 0.5 0.5 1"/>
                </material>                 
            </visual>
            <collision>
                <geometry>
                      <mesh filename="file:///$(find arm_01)/description/meshes/armA/armA_6.stl" 
                        scale="0.004 0.004 0.004" />
                </geometry>
              </collision>
        </link>

        <!-- Gazebo Colors -->
        <gazebo reference="base_0">
            <material>Gazebo/Gray</material>
        </gazebo>
        <gazebo reference="link1">
            <material>Gazebo/White</material>
        </gazebo>
        <gazebo reference="link2">
            <material>Gazebo/Gray</material>
        </gazebo>
        <gazebo reference="link3">
            <material>Gazebo/White</material>
        </gazebo>
        <gazebo reference="link4">
            <material>Gazebo/Gray</material>
        </gazebo>
        <gazebo reference="link5">
            <material>Gazebo/White</material>
        </gazebo>
        <gazebo reference="link6">
            <material>Gazebo/Gray</material>
        </gazebo>

        <!-- the following lines instantiates all the info described in the files:
         macro.gazebo_config_control.xacro, transmissions,  internal_config, macro.bumper_config  by david-->
        <xacro:config_ctr_gazebo /> 
        <xacro:dsr_transmission />
        <xacro:dsr_config_coeff />
        <xacro:bumper_ctr_sensor />

    </xacro:macro>
</robot>
