<?xml version="1.0"?>
<robot xmlns:xacro="http://www.ros.org/wiki/xacro">
    <xacro:include filename="colors.xacro" />
    <!-- xacro:include filename="inertial_macros.xacro" / -->

    <xacro:property name="wheel_radius" value="0.04" />
    <xacro:property name="wheel_length" value="0.05" />
    <xacro:property name="wheel_color_name" value="red" />
    <xacro:property name="wheel_color_rgb" value="1 0 0 1" />

    <xacro:macro name="box_link" params="name size color color_rgb mass mass_x mass_y mass_z" >
        <link name="${name}">
            <visual>
                <geometry>
                    <box size="${size}"/>
                </geometry>
                <material name="${color}">
                    <color rgba="${color_rgb}"/>
                </material>
            </visual>
            <collision>
                <origin xyz="${mass_x/2} ${mass_y/2} ${mass_z/2}" rpy="0 0 0"/>
                <geometry>
                    <box size="${size}"/>
                </geometry>
            </collision>
            <xacro:inertial_box mass="${mass}" x="${mass_x}" y="${mass_y}" z="${mass_z}">
                <origin xyz="${mass_x} ${mass_y} ${mass_z}" rpy="0 0 0"/>
            </xacro:inertial_box>                
        </link>
    </xacro:macro>

    <xacro:macro name="wheel" params="name mass">
        <link name="${name}">
            <visual>
                <geometry>
                    <cylinder radius="${wheel_radius}" length="${wheel_length}" />
                </geometry>
                <material name="${wheel_color_name}">
                    <color rgba="${wheel_color_rgb}"/>
                </material>
            </visual>
            <collision>
                <geometry>
                    <cylinder length="${wheel_length}" radius="${wheel_radius}" />/>
                </geometry>
                <material name="blue"/>
            </collision>
            <xacro:inertial_cylinder mass="${mass}" length="${wheel_length}" radius="${wheel_radius}">
                <origin xyz="0 0 0" rpy="0 0 0"/>
            </xacro:inertial_cylinder>              
        </link> 
    </xacro:macro>  

    <!-- xacro:macro name="static_joint" params="name parent child">
        <joint name="${name}" type="continuous">
            <parent link="${parent}" />
            <child link="${child}" />
            <origin xyz="0 0 0" rpy="0 0 0"/>
        </joint>
    </xacro:macro -->

    <xacro:macro name="wheel_joint" params="name parent child xyz ">
        <joint name="${name}" type="continuous">
            <parent link="${parent}" />
            <child link="${child}" />
            <origin xyz="${xyz}" rpy="${pi/2} 0 0"/>
            <axis rpy="0 0 0" xyz="0 0 1"/>
            <!-- limit effort="1" velocity="1"/>
            <joint_properties damping="1.0" friction="1.0"/ -->
        </joint>
    </xacro:macro>   

    <!-- Robot Description -->

    <!-- xacro:box_link name="base_link" size="0.6 0.3 0.1" color="red" color_rgb="0 1 0 1" 
         mass="0.5" mass_x="0.3" mass_y="0.15" mass_z="0.05"/ -->
    <link name="base_link">
    </link>         

    <xacro:box_link name="chassis" size="0.6 0.3 0.1" color="green" color_rgb="0 1 0 1" 
         mass="0.5" mass_x="0.3" mass_y="0.15" mass_z="0.05"/>

    <joint name="chassis_joint" type="fixed">
        <parent link="base_link"/>
        <child link="chassis"/>
        <origin xyz="0 0 0"/>
    </joint>

    <xacro:wheel name="right_wheel_frontside" mass="0.1" />
    <xacro:wheel_joint name="base_link_right_wheel_frontside" parent="base_link" 
        child="right_wheel_frontside" xyz="0.2 -0.2 -0.05" />

    <xacro:wheel name="right_wheel_backside" mass="0.1" />
    <xacro:wheel_joint name="base_link_right_wheel_backside" parent="base_link" 
        child="right_wheel_backside" xyz="-0.2 -0.2 -0.05" />

    <xacro:wheel name="left_wheel_frontside" mass="0.1" /> 
    <xacro:wheel_joint name="base_link_left_wheel_frontside" parent="base_link" 
        child="left_wheel_frontside" xyz="0.2 0.2 -0.05" />

    <xacro:wheel name="left_wheel_backside" mass="0.1" /> 
    <xacro:wheel_joint name="base_link_left_wheel_backside" parent="base_link" 
        child="left_wheel_backside" xyz="-0.2 0.2 -0.05" />

    <!-- Gazebo Colors -->
    <gazebo reference="chasis">
        <material>Gazebo/Green</material>
    </gazebo>
    <gazebo reference="right_wheel_frontside">
        <material>Gazebo/Red</material>
    </gazebo>
    <gazebo reference="right_wheel_backside">
        <material>Gazebo/Red</material>
    </gazebo>
    <gazebo reference="left_wheel_frontside">
        <material>Gazebo/Red</material>
    </gazebo>
    <gazebo reference="left_wheel_backside">
        <material>Gazebo/Red</material>
    </gazebo>

</robot>

